2021-03-08 15:44:37,630 ERROR: Exception on /confirma_solicitud [GET] [in c:\users\erezzonico\proyectos\python\borisappfront\env\lib\site-packages\flask\app.py:1892]
Traceback (most recent call last):
  File "c:\users\erezzonico\proyectos\python\borisappfront\env\lib\site-packages\flask\app.py", line 2447, in wsgi_app
    response = self.full_dispatch_request()
  File "c:\users\erezzonico\proyectos\python\borisappfront\env\lib\site-packages\flask\app.py", line 1952, in full_dispatch_request
    rv = self.handle_user_exception(e)
  File "c:\users\erezzonico\proyectos\python\borisappfront\env\lib\site-packages\flask\app.py", line 1821, in handle_user_exception
    reraise(exc_type, exc_value, tb)
  File "c:\users\erezzonico\proyectos\python\borisappfront\env\lib\site-packages\flask\_compat.py", line 39, in reraise
    raise value
  File "c:\users\erezzonico\proyectos\python\borisappfront\env\lib\site-packages\flask\app.py", line 1950, in full_dispatch_request
    rv = self.dispatch_request()
  File "c:\users\erezzonico\proyectos\python\borisappfront\env\lib\site-packages\flask\app.py", line 1936, in dispatch_request
    return self.view_functions[rule.endpoint](**req.view_args)
  File "C:\Users\erezzonico\Proyectos\Python\BorisAppFront\app\main\routes.py", line 161, in confirma_solicitud
    envio = crea_envio(company, user, order, productos, metodo_envio)
  File "C:\Users\erezzonico\Proyectos\Python\BorisAppFront\app\main\interface.py", line 262, in crea_envio
    user=user, envio=solicitud_envio),
  File "c:\users\erezzonico\proyectos\python\borisappfront\env\lib\site-packages\flask\templating.py", line 140, in render_template
    ctx.app,
  File "c:\users\erezzonico\proyectos\python\borisappfront\env\lib\site-packages\flask\templating.py", line 120, in _render
    rv = template.render(context)
  File "c:\users\erezzonico\proyectos\python\borisappfront\env\lib\site-packages\jinja2\environment.py", line 1090, in render
    self.environment.handle_exception()
  File "c:\users\erezzonico\proyectos\python\borisappfront\env\lib\site-packages\jinja2\environment.py", line 832, in handle_exception
    reraise(*rewrite_traceback_stack(source=source))
  File "c:\users\erezzonico\proyectos\python\borisappfront\env\lib\site-packages\jinja2\_compat.py", line 28, in reraise
    raise value.with_traceback(tb)
  File "C:\Users\erezzonico\Proyectos\Python\BorisAppFront\app\templates\email\1447373\pedido_listo.txt", line 20, in top-level template code
    http://ec2-54-208-172-198.compute-1.amazonaws.com/tracking/{{order.order_number}}
  File "c:\users\erezzonico\proyectos\python\borisappfront\env\lib\site-packages\jinja2\environment.py", line 471, in getattr
    return getattr(obj, attribute)
jinja2.exceptions.UndefinedError: 'order' is undefined
2021-03-08 15:45:25,844 INFO: Boris startup [in C:\Users\erezzonico\Proyectos\Python\BorisAppFront\app\__init__.py:63]
2021-03-15 08:47:28,865 INFO: Boris startup [in C:\Users\erezzonico\Proyectos\Python\BorisAppFront\app\__init__.py:63]
2021-03-15 09:05:36,024 INFO: Boris startup [in C:\Users\erezzonico\Proyectos\Python\BorisAppFront\app\__init__.py:63]
2021-03-15 09:25:19,317 INFO: Boris startup [in C:\Users\erezzonico\Proyectos\Python\BorisAppFront\app\__init__.py:63]
2021-03-15 09:25:53,618 INFO: Boris startup [in C:\Users\erezzonico\Proyectos\Python\BorisAppFront\app\__init__.py:63]
2021-03-15 09:50:00,224 INFO: Boris startup [in C:\Users\erezzonico\Proyectos\Python\BorisAppFront\app\__init__.py:63]
2021-03-15 09:50:26,139 ERROR: Exception on /Confirmar [POST] [in c:\users\erezzonico\proyectos\python\borisappfront\env\lib\site-packages\flask\app.py:1892]
Traceback (most recent call last):
  File "c:\users\erezzonico\proyectos\python\borisappfront\env\lib\site-packages\flask\app.py", line 2447, in wsgi_app
    response = self.full_dispatch_request()
  File "c:\users\erezzonico\proyectos\python\borisappfront\env\lib\site-packages\flask\app.py", line 1952, in full_dispatch_request
    rv = self.handle_user_exception(e)
  File "c:\users\erezzonico\proyectos\python\borisappfront\env\lib\site-packages\flask\app.py", line 1821, in handle_user_exception
    reraise(exc_type, exc_value, tb)
  File "c:\users\erezzonico\proyectos\python\borisappfront\env\lib\site-packages\flask\_compat.py", line 39, in reraise
    raise value
  File "c:\users\erezzonico\proyectos\python\borisappfront\env\lib\site-packages\flask\app.py", line 1950, in full_dispatch_request
    rv = self.dispatch_request()
  File "c:\users\erezzonico\proyectos\python\borisappfront\env\lib\site-packages\flask\app.py", line 1936, in dispatch_request
    return self.view_functions[rule.endpoint](**req.view_args)
  File "C:\Users\erezzonico\Proyectos\Python\BorisAppFront\app\main\routes.py", line 128, in confirma_cambios
    precio_envio = cotiza_envio(company, user, order, productos)
NameError: name 'cotiza_envio' is not defined
2021-03-15 09:51:09,806 INFO: Boris startup [in C:\Users\erezzonico\Proyectos\Python\BorisAppFront\app\__init__.py:63]
2021-03-15 09:51:13,136 ERROR: Exception on /Confirmar [POST] [in c:\users\erezzonico\proyectos\python\borisappfront\env\lib\site-packages\flask\app.py:1892]
Traceback (most recent call last):
  File "c:\users\erezzonico\proyectos\python\borisappfront\env\lib\site-packages\flask\app.py", line 2447, in wsgi_app
    response = self.full_dispatch_request()
  File "c:\users\erezzonico\proyectos\python\borisappfront\env\lib\site-packages\flask\app.py", line 1952, in full_dispatch_request
    rv = self.handle_user_exception(e)
  File "c:\users\erezzonico\proyectos\python\borisappfront\env\lib\site-packages\flask\app.py", line 1821, in handle_user_exception
    reraise(exc_type, exc_value, tb)
  File "c:\users\erezzonico\proyectos\python\borisappfront\env\lib\site-packages\flask\_compat.py", line 39, in reraise
    raise value
  File "c:\users\erezzonico\proyectos\python\borisappfront\env\lib\site-packages\flask\app.py", line 1950, in full_dispatch_request
    rv = self.dispatch_request()
  File "c:\users\erezzonico\proyectos\python\borisappfront\env\lib\site-packages\flask\app.py", line 1936, in dispatch_request
    return self.view_functions[rule.endpoint](**req.view_args)
  File "C:\Users\erezzonico\Proyectos\Python\BorisAppFront\app\main\routes.py", line 128, in confirma_cambios
    precio_envio = cotiza_envio(company, user, order, productos)
TypeError: cotiza_envio() missing 1 required positional argument: 'correo'
2021-03-15 09:51:21,309 ERROR: Exception on /Confirmar [POST] [in c:\users\erezzonico\proyectos\python\borisappfront\env\lib\site-packages\flask\app.py:1892]
Traceback (most recent call last):
  File "c:\users\erezzonico\proyectos\python\borisappfront\env\lib\site-packages\flask\app.py", line 2447, in wsgi_app
    response = self.full_dispatch_request()
  File "c:\users\erezzonico\proyectos\python\borisappfront\env\lib\site-packages\flask\app.py", line 1952, in full_dispatch_request
    rv = self.handle_user_exception(e)
  File "c:\users\erezzonico\proyectos\python\borisappfront\env\lib\site-packages\flask\app.py", line 1821, in handle_user_exception
    reraise(exc_type, exc_value, tb)
  File "c:\users\erezzonico\proyectos\python\borisappfront\env\lib\site-packages\flask\_compat.py", line 39, in reraise
    raise value
  File "c:\users\erezzonico\proyectos\python\borisappfront\env\lib\site-packages\flask\app.py", line 1950, in full_dispatch_request
    rv = self.dispatch_request()
  File "c:\users\erezzonico\proyectos\python\borisappfront\env\lib\site-packages\flask\app.py", line 1936, in dispatch_request
    return self.view_functions[rule.endpoint](**req.view_args)
  File "C:\Users\erezzonico\Proyectos\Python\BorisAppFront\app\main\routes.py", line 128, in confirma_cambios
    precio_envio = cotiza_envio(company, user, order, productos)
TypeError: cotiza_envio() missing 1 required positional argument: 'correo'
2021-03-15 09:52:52,566 INFO: Boris startup [in C:\Users\erezzonico\Proyectos\Python\BorisAppFront\app\__init__.py:63]
2021-03-15 09:52:59,240 ERROR: Exception on /Confirmar [POST] [in c:\users\erezzonico\proyectos\python\borisappfront\env\lib\site-packages\flask\app.py:1892]
Traceback (most recent call last):
  File "c:\users\erezzonico\proyectos\python\borisappfront\env\lib\site-packages\flask\app.py", line 2447, in wsgi_app
    response = self.full_dispatch_request()
  File "c:\users\erezzonico\proyectos\python\borisappfront\env\lib\site-packages\flask\app.py", line 1952, in full_dispatch_request
    rv = self.handle_user_exception(e)
  File "c:\users\erezzonico\proyectos\python\borisappfront\env\lib\site-packages\flask\app.py", line 1821, in handle_user_exception
    reraise(exc_type, exc_value, tb)
  File "c:\users\erezzonico\proyectos\python\borisappfront\env\lib\site-packages\flask\_compat.py", line 39, in reraise
    raise value
  File "c:\users\erezzonico\proyectos\python\borisappfront\env\lib\site-packages\flask\app.py", line 1950, in full_dispatch_request
    rv = self.dispatch_request()
  File "c:\users\erezzonico\proyectos\python\borisappfront\env\lib\site-packages\flask\app.py", line 1936, in dispatch_request
    return self.view_functions[rule.endpoint](**req.view_args)
  File "C:\Users\erezzonico\Proyectos\Python\BorisAppFront\app\main\routes.py", line 128, in confirma_cambios
    precio_envio = cotiza_envio(company, user, order, productos, company.correo_usado)
  File "C:\Users\erezzonico\Proyectos\Python\BorisAppFront\app\main\interface.py", line 339, in cotiza_envio
    flash('Hubo un problema con la generación del evío. Error {} - {}'.format(solicitud.code, solicitud.stauts))
AttributeError: 'Response' object has no attribute 'code'
2021-03-15 09:53:37,956 INFO: Boris startup [in C:\Users\erezzonico\Proyectos\Python\BorisAppFront\app\__init__.py:63]
2021-03-15 09:56:42,917 INFO: Boris startup [in C:\Users\erezzonico\Proyectos\Python\BorisAppFront\app\__init__.py:63]
2021-03-15 10:02:01,672 INFO: Boris startup [in C:\Users\erezzonico\Proyectos\Python\BorisAppFront\app\__init__.py:63]
