2021-06-08 13:47:19,160 ERROR: Exception on /empresa/chequear [POST] [in c:\users\erezzonico\proyectos\python\borisappfront\env\lib\site-packages\flask\app.py:1892]
Traceback (most recent call last):
  File "c:\users\erezzonico\proyectos\python\borisappfront\env\lib\site-packages\flask\app.py", line 2447, in wsgi_app
    response = self.full_dispatch_request()
  File "c:\users\erezzonico\proyectos\python\borisappfront\env\lib\site-packages\flask\app.py", line 1952, in full_dispatch_request
    rv = self.handle_user_exception(e)
  File "c:\users\erezzonico\proyectos\python\borisappfront\env\lib\site-packages\flask\app.py", line 1821, in handle_user_exception
    reraise(exc_type, exc_value, tb)
  File "c:\users\erezzonico\proyectos\python\borisappfront\env\lib\site-packages\flask\_compat.py", line 39, in reraise
    raise value
  File "c:\users\erezzonico\proyectos\python\borisappfront\env\lib\site-packages\flask\app.py", line 1950, in full_dispatch_request
    rv = self.dispatch_request()
  File "c:\users\erezzonico\proyectos\python\borisappfront\env\lib\site-packages\flask\app.py", line 1936, in dispatch_request
    return self.view_functions[rule.endpoint](**req.view_args)
  File "C:\Users\erezzonico\Proyectos\Python\BorisAppFront\app\main\routes.py", line 217, in chequear_empresa
    actualiza = actualizar_store(store)
  File "C:\Users\erezzonico\Proyectos\Python\BorisAppFront\app\main\interface.py", line 564, in actualizar_store
    empresa.shipping_country = store['.shipping_country']
KeyError: '.shipping_country'
2021-06-08 13:47:58,892 INFO: Boris startup [in C:\Users\erezzonico\Proyectos\Python\BorisAppFront\app\__init__.py:63]
2021-06-08 14:00:13,758 INFO: Boris startup [in C:\Users\erezzonico\Proyectos\Python\BorisAppFront\app\__init__.py:63]
2021-06-08 14:00:18,037 INFO: Boris startup [in C:\Users\erezzonico\Proyectos\Python\BorisAppFront\app\__init__.py:63]
2021-06-08 14:00:59,418 ERROR: Exception on /empresa/chequear [POST] [in c:\users\erezzonico\proyectos\python\borisappfront\env\lib\site-packages\flask\app.py:1892]
Traceback (most recent call last):
  File "c:\users\erezzonico\proyectos\python\borisappfront\env\lib\site-packages\flask\app.py", line 2447, in wsgi_app
    response = self.full_dispatch_request()
  File "c:\users\erezzonico\proyectos\python\borisappfront\env\lib\site-packages\flask\app.py", line 1952, in full_dispatch_request
    rv = self.handle_user_exception(e)
  File "c:\users\erezzonico\proyectos\python\borisappfront\env\lib\site-packages\flask\app.py", line 1821, in handle_user_exception
    reraise(exc_type, exc_value, tb)
  File "c:\users\erezzonico\proyectos\python\borisappfront\env\lib\site-packages\flask\_compat.py", line 39, in reraise
    raise value
  File "c:\users\erezzonico\proyectos\python\borisappfront\env\lib\site-packages\flask\app.py", line 1950, in full_dispatch_request
    rv = self.dispatch_request()
  File "c:\users\erezzonico\proyectos\python\borisappfront\env\lib\site-packages\flask\app.py", line 1936, in dispatch_request
    return self.view_functions[rule.endpoint](**req.view_args)
  File "C:\Users\erezzonico\Proyectos\Python\BorisAppFront\app\main\routes.py", line 219, in chequear_empresa
    actualiza = crear_store(store)
  File "C:\Users\erezzonico\Proyectos\Python\BorisAppFront\app\main\interface.py", line 577, in crear_store
    url='/static/conf/'+empresa.store_name+'.json'
NameError: name 'empresa' is not defined
2021-06-08 14:02:03,952 INFO: Boris startup [in C:\Users\erezzonico\Proyectos\Python\BorisAppFront\app\__init__.py:63]
2021-06-08 14:02:14,650 ERROR: Exception on /empresa/chequear [POST] [in c:\users\erezzonico\proyectos\python\borisappfront\env\lib\site-packages\flask\app.py:1892]
Traceback (most recent call last):
  File "c:\users\erezzonico\proyectos\python\borisappfront\env\lib\site-packages\flask\app.py", line 2447, in wsgi_app
    response = self.full_dispatch_request()
  File "c:\users\erezzonico\proyectos\python\borisappfront\env\lib\site-packages\flask\app.py", line 1952, in full_dispatch_request
    rv = self.handle_user_exception(e)
  File "c:\users\erezzonico\proyectos\python\borisappfront\env\lib\site-packages\flask\app.py", line 1821, in handle_user_exception
    reraise(exc_type, exc_value, tb)
  File "c:\users\erezzonico\proyectos\python\borisappfront\env\lib\site-packages\flask\_compat.py", line 39, in reraise
    raise value
  File "c:\users\erezzonico\proyectos\python\borisappfront\env\lib\site-packages\flask\app.py", line 1950, in full_dispatch_request
    rv = self.dispatch_request()
  File "c:\users\erezzonico\proyectos\python\borisappfront\env\lib\site-packages\flask\app.py", line 1936, in dispatch_request
    return self.view_functions[rule.endpoint](**req.view_args)
  File "C:\Users\erezzonico\Proyectos\Python\BorisAppFront\app\main\routes.py", line 219, in chequear_empresa
    actualiza = crear_store(store)
  File "C:\Users\erezzonico\Proyectos\Python\BorisAppFront\app\main\interface.py", line 577, in crear_store
    url='/static/conf/'+store.store_name+'.json'
AttributeError: 'dict' object has no attribute 'store_name'
2021-06-08 14:03:00,257 INFO: Boris startup [in C:\Users\erezzonico\Proyectos\Python\BorisAppFront\app\__init__.py:63]
2021-06-08 14:03:03,969 ERROR: Exception on /empresa/chequear [POST] [in c:\users\erezzonico\proyectos\python\borisappfront\env\lib\site-packages\flask\app.py:1892]
Traceback (most recent call last):
  File "c:\users\erezzonico\proyectos\python\borisappfront\env\lib\site-packages\flask\app.py", line 2447, in wsgi_app
    response = self.full_dispatch_request()
  File "c:\users\erezzonico\proyectos\python\borisappfront\env\lib\site-packages\flask\app.py", line 1952, in full_dispatch_request
    rv = self.handle_user_exception(e)
  File "c:\users\erezzonico\proyectos\python\borisappfront\env\lib\site-packages\flask\app.py", line 1821, in handle_user_exception
    reraise(exc_type, exc_value, tb)
  File "c:\users\erezzonico\proyectos\python\borisappfront\env\lib\site-packages\flask\_compat.py", line 39, in reraise
    raise value
  File "c:\users\erezzonico\proyectos\python\borisappfront\env\lib\site-packages\flask\app.py", line 1950, in full_dispatch_request
    rv = self.dispatch_request()
  File "c:\users\erezzonico\proyectos\python\borisappfront\env\lib\site-packages\flask\app.py", line 1936, in dispatch_request
    return self.view_functions[rule.endpoint](**req.view_args)
  File "C:\Users\erezzonico\Proyectos\Python\BorisAppFront\app\main\routes.py", line 219, in chequear_empresa
    actualiza = crear_store(store)
  File "C:\Users\erezzonico\Proyectos\Python\BorisAppFront\app\main\interface.py", line 617, in crear_store
    with open(url, "w+") as outfile:
FileNotFoundError: [Errno 2] No such file or directory: '/static/conf/Abundancia por designio.json'
2021-06-08 14:06:37,302 INFO: Boris startup [in C:\Users\erezzonico\Proyectos\Python\BorisAppFront\app\__init__.py:63]
2021-06-08 14:08:12,192 INFO: Boris startup [in C:\Users\erezzonico\Proyectos\Python\BorisAppFront\app\__init__.py:63]
2021-06-08 14:08:16,052 INFO: Boris startup [in C:\Users\erezzonico\Proyectos\Python\BorisAppFront\app\__init__.py:63]
2021-06-08 14:08:33,962 ERROR: Exception on /buscar [GET] [in c:\users\erezzonico\proyectos\python\borisappfront\env\lib\site-packages\flask\app.py:1892]
Traceback (most recent call last):
  File "c:\users\erezzonico\proyectos\python\borisappfront\env\lib\site-packages\flask\app.py", line 2447, in wsgi_app
    response = self.full_dispatch_request()
  File "c:\users\erezzonico\proyectos\python\borisappfront\env\lib\site-packages\flask\app.py", line 1952, in full_dispatch_request
    rv = self.handle_user_exception(e)
  File "c:\users\erezzonico\proyectos\python\borisappfront\env\lib\site-packages\flask\app.py", line 1821, in handle_user_exception
    reraise(exc_type, exc_value, tb)
  File "c:\users\erezzonico\proyectos\python\borisappfront\env\lib\site-packages\flask\_compat.py", line 39, in reraise
    raise value
  File "c:\users\erezzonico\proyectos\python\borisappfront\env\lib\site-packages\flask\app.py", line 1950, in full_dispatch_request
    rv = self.dispatch_request()
  File "c:\users\erezzonico\proyectos\python\borisappfront\env\lib\site-packages\flask\app.py", line 1936, in dispatch_request
    return self.view_functions[rule.endpoint](**req.view_args)
  File "C:\Users\erezzonico\Proyectos\Python\BorisAppFront\app\main\routes.py", line 56, in buscar
    unaEmpresa = buscar_empresa(request.args['empresa'])
  File "C:\Users\erezzonico\Proyectos\Python\BorisAppFront\app\main\interface.py", line 101, in buscar_empresa
    settings = guardar_settings(empresa_tmp.param_config)
  File "C:\Users\erezzonico\Proyectos\Python\BorisAppFront\app\main\interface.py", line 193, in guardar_settings
    with open(url, encoding='utf-8') as json_file:
FileNotFoundError: [Errno 2] No such file or directory: 'app/static/conf/abundancia.json'
2021-06-08 14:10:53,682 INFO: Boris startup [in C:\Users\erezzonico\Proyectos\Python\BorisAppFront\app\__init__.py:63]
2021-06-08 14:11:07,948 INFO: Boris startup [in C:\Users\erezzonico\Proyectos\Python\BorisAppFront\app\__init__.py:63]
2021-06-08 14:19:23,037 INFO: Boris startup [in C:\Users\erezzonico\Proyectos\Python\BorisAppFront\app\__init__.py:63]
2021-06-08 15:01:13,755 INFO: Boris startup [in C:\Users\erezzonico\Proyectos\Python\BorisAppFront\app\__init__.py:63]
