2021-04-02 17:00:09,485 ERROR: Exception on /buscar [POST] [in c:\users\erezzonico\proyectos\python\borisappfront\env\lib\site-packages\flask\app.py:1892]
Traceback (most recent call last):
  File "c:\users\erezzonico\proyectos\python\borisappfront\env\lib\site-packages\flask\app.py", line 2447, in wsgi_app
    response = self.full_dispatch_request()
  File "c:\users\erezzonico\proyectos\python\borisappfront\env\lib\site-packages\flask\app.py", line 1952, in full_dispatch_request
    rv = self.handle_user_exception(e)
  File "c:\users\erezzonico\proyectos\python\borisappfront\env\lib\site-packages\flask\app.py", line 1821, in handle_user_exception
    reraise(exc_type, exc_value, tb)
  File "c:\users\erezzonico\proyectos\python\borisappfront\env\lib\site-packages\flask\_compat.py", line 39, in reraise
    raise value
  File "c:\users\erezzonico\proyectos\python\borisappfront\env\lib\site-packages\flask\app.py", line 1950, in full_dispatch_request
    rv = self.dispatch_request()
  File "c:\users\erezzonico\proyectos\python\borisappfront\env\lib\site-packages\flask\app.py", line 1936, in dispatch_request
    return self.view_functions[rule.endpoint](**req.view_args)
  File "C:\Users\erezzonico\Proyectos\Python\BorisAppFront\app\main\routes.py", line 61, in buscar
    pedido = buscar_pedido(unaEmpresa, form)
  File "C:\Users\erezzonico\Proyectos\Python\BorisAppFront\app\main\interface.py", line 26, in buscar_pedido
    'Authentication': empresa.platform_token_type+' '+empresa.platform_access_token
TypeError: unsupported operand type(s) for +: 'NoneType' and 'str'
2021-04-02 17:00:58,368 ERROR: Exception on /pedidos [POST] [in c:\users\erezzonico\proyectos\python\borisappfront\env\lib\site-packages\flask\app.py:1892]
Traceback (most recent call last):
  File "c:\users\erezzonico\proyectos\python\borisappfront\env\lib\site-packages\flask\app.py", line 2447, in wsgi_app
    response = self.full_dispatch_request()
  File "c:\users\erezzonico\proyectos\python\borisappfront\env\lib\site-packages\flask\app.py", line 1952, in full_dispatch_request
    rv = self.handle_user_exception(e)
  File "c:\users\erezzonico\proyectos\python\borisappfront\env\lib\site-packages\flask\app.py", line 1821, in handle_user_exception
    reraise(exc_type, exc_value, tb)
  File "c:\users\erezzonico\proyectos\python\borisappfront\env\lib\site-packages\flask\_compat.py", line 39, in reraise
    raise value
  File "c:\users\erezzonico\proyectos\python\borisappfront\env\lib\site-packages\flask\app.py", line 1950, in full_dispatch_request
    rv = self.dispatch_request()
  File "c:\users\erezzonico\proyectos\python\borisappfront\env\lib\site-packages\flask\app.py", line 1936, in dispatch_request
    return self.view_functions[rule.endpoint](**req.view_args)
  File "C:\Users\erezzonico\Proyectos\Python\BorisAppFront\app\main\routes.py", line 99, in pedidos
    alternativas = buscar_alternativas(session['store'], item.prod_id, motivo, item.variant)
  File "C:\Users\erezzonico\Proyectos\Python\BorisAppFront\app\main\interface.py", line 80, in buscar_alternativas
    for x in product['variants']:
KeyError: 'variants'
2021-04-02 17:07:20,546 INFO: Boris startup [in C:\Users\erezzonico\Proyectos\Python\BorisAppFront\app\__init__.py:63]
2021-04-02 17:07:37,059 ERROR: Exception on /buscar [POST] [in c:\users\erezzonico\proyectos\python\borisappfront\env\lib\site-packages\flask\app.py:1892]
Traceback (most recent call last):
  File "c:\users\erezzonico\proyectos\python\borisappfront\env\lib\site-packages\sqlalchemy\engine\base.py", line 1277, in _execute_context
    cursor, statement, parameters, context
  File "c:\users\erezzonico\proyectos\python\borisappfront\env\lib\site-packages\sqlalchemy\engine\default.py", line 593, in do_execute
    cursor.execute(statement, parameters)
sqlite3.OperationalError: table company has no column named company_main_language

The above exception was the direct cause of the following exception:

Traceback (most recent call last):
  File "c:\users\erezzonico\proyectos\python\borisappfront\env\lib\site-packages\flask\app.py", line 2447, in wsgi_app
    response = self.full_dispatch_request()
  File "c:\users\erezzonico\proyectos\python\borisappfront\env\lib\site-packages\flask\app.py", line 1952, in full_dispatch_request
    rv = self.handle_user_exception(e)
  File "c:\users\erezzonico\proyectos\python\borisappfront\env\lib\site-packages\flask\app.py", line 1821, in handle_user_exception
    reraise(exc_type, exc_value, tb)
  File "c:\users\erezzonico\proyectos\python\borisappfront\env\lib\site-packages\flask\_compat.py", line 39, in reraise
    raise value
  File "c:\users\erezzonico\proyectos\python\borisappfront\env\lib\site-packages\flask\app.py", line 1950, in full_dispatch_request
    rv = self.dispatch_request()
  File "c:\users\erezzonico\proyectos\python\borisappfront\env\lib\site-packages\flask\app.py", line 1936, in dispatch_request
    return self.view_functions[rule.endpoint](**req.view_args)
  File "C:\Users\erezzonico\Proyectos\Python\BorisAppFront\app\main\routes.py", line 67, in buscar
    cargar_pedido(unaEmpresa, pedido)
  File "C:\Users\erezzonico\Proyectos\Python\BorisAppFront\app\main\interface.py", line 424, in cargar_pedido
    db.session.commit()
  File "c:\users\erezzonico\proyectos\python\borisappfront\env\lib\site-packages\sqlalchemy\orm\scoping.py", line 163, in do
    return getattr(self.registry(), name)(*args, **kwargs)
  File "c:\users\erezzonico\proyectos\python\borisappfront\env\lib\site-packages\sqlalchemy\orm\session.py", line 1042, in commit
    self.transaction.commit()
  File "c:\users\erezzonico\proyectos\python\borisappfront\env\lib\site-packages\sqlalchemy\orm\session.py", line 504, in commit
    self._prepare_impl()
  File "c:\users\erezzonico\proyectos\python\borisappfront\env\lib\site-packages\sqlalchemy\orm\session.py", line 483, in _prepare_impl
    self.session.flush()
  File "c:\users\erezzonico\proyectos\python\borisappfront\env\lib\site-packages\sqlalchemy\orm\session.py", line 2536, in flush
    self._flush(objects)
  File "c:\users\erezzonico\proyectos\python\borisappfront\env\lib\site-packages\sqlalchemy\orm\session.py", line 2678, in _flush
    transaction.rollback(_capture_exception=True)
  File "c:\users\erezzonico\proyectos\python\borisappfront\env\lib\site-packages\sqlalchemy\util\langhelpers.py", line 70, in __exit__
    with_traceback=exc_tb,
  File "c:\users\erezzonico\proyectos\python\borisappfront\env\lib\site-packages\sqlalchemy\util\compat.py", line 182, in raise_
    raise exception
  File "c:\users\erezzonico\proyectos\python\borisappfront\env\lib\site-packages\sqlalchemy\orm\session.py", line 2638, in _flush
    flush_context.execute()
  File "c:\users\erezzonico\proyectos\python\borisappfront\env\lib\site-packages\sqlalchemy\orm\unitofwork.py", line 422, in execute
    rec.execute(self)
  File "c:\users\erezzonico\proyectos\python\borisappfront\env\lib\site-packages\sqlalchemy\orm\unitofwork.py", line 589, in execute
    uow,
  File "c:\users\erezzonico\proyectos\python\borisappfront\env\lib\site-packages\sqlalchemy\orm\persistence.py", line 245, in save_obj
    insert,
  File "c:\users\erezzonico\proyectos\python\borisappfront\env\lib\site-packages\sqlalchemy\orm\persistence.py", line 1136, in _emit_insert_statements
    statement, params
  File "c:\users\erezzonico\proyectos\python\borisappfront\env\lib\site-packages\sqlalchemy\engine\base.py", line 1011, in execute
    return meth(self, multiparams, params)
  File "c:\users\erezzonico\proyectos\python\borisappfront\env\lib\site-packages\sqlalchemy\sql\elements.py", line 298, in _execute_on_connection
    return connection._execute_clauseelement(self, multiparams, params)
  File "c:\users\erezzonico\proyectos\python\borisappfront\env\lib\site-packages\sqlalchemy\engine\base.py", line 1130, in _execute_clauseelement
    distilled_params,
  File "c:\users\erezzonico\proyectos\python\borisappfront\env\lib\site-packages\sqlalchemy\engine\base.py", line 1317, in _execute_context
    e, statement, parameters, cursor, context
  File "c:\users\erezzonico\proyectos\python\borisappfront\env\lib\site-packages\sqlalchemy\engine\base.py", line 1511, in _handle_dbapi_exception
    sqlalchemy_exception, with_traceback=exc_info[2], from_=e
  File "c:\users\erezzonico\proyectos\python\borisappfront\env\lib\site-packages\sqlalchemy\util\compat.py", line 182, in raise_
    raise exception
  File "c:\users\erezzonico\proyectos\python\borisappfront\env\lib\site-packages\sqlalchemy\engine\base.py", line 1277, in _execute_context
    cursor, statement, parameters, context
  File "c:\users\erezzonico\proyectos\python\borisappfront\env\lib\site-packages\sqlalchemy\engine\default.py", line 593, in do_execute
    cursor.execute(statement, parameters)
sqlalchemy.exc.OperationalError: (sqlite3.OperationalError) table company has no column named company_main_language
[SQL: INSERT INTO company (platform, platform_token_type, platform_access_token, store_id, company_main_language, company_main_currency, company_country, company_name, admin_email, communication_email, logo, contact_name, contact_phone, contact_email, correo_usado, correo_apikey, correo_id, correo_test, correo_apikey_test, correo_id_test, shipping_address, shipping_number, shipping_floor, shipping_zipcode, shipping_city, shipping_province, shipping_country, shipping_info) VALUES (?, ?, ?, ?, ?, ?, ?, ?, ?, ?, ?, ?, ?, ?, ?, ?, ?, ?, ?, ?, ?, ?, ?, ?, ?, ?, ?, ?)]
[parameters: ('tiendanube', 'bearer', 'd3209f9f749a749ee205e2f0e150f732bbe8b997', '1631829', 'es', 'ARS', 'AR', 'demo debocaenboca', 'leilasaid@hotmail.com', 'soporte@borisreturns.com', '//d2r9epyceweg5n.cloudfront.net/stores/001/631/829/themes/common/logo-343539575-1617381511-501e7beeaea7770b915d4300c320ad871617381511.png?0', 'Leila Almacen', '4500 4500', 'erezzoni@yahoo.com', 'Ninguno', '', '', None, None, None, 'Virrey Loreto', '2253', '', '1426', 'CABA', 'CABA', 'AR', 'dejar en recepcion')]
(Background on this error at: http://sqlalche.me/e/13/e3q8)
