2021-04-02 17:08:01,820 INFO: Boris startup [in C:\Users\erezzonico\Proyectos\Python\BorisAppFront\app\__init__.py:63]
2021-04-02 17:08:06,618 INFO: Boris startup [in C:\Users\erezzonico\Proyectos\Python\BorisAppFront\app\__init__.py:63]
2021-04-02 17:08:14,076 INFO: Boris startup [in C:\Users\erezzonico\Proyectos\Python\BorisAppFront\app\__init__.py:63]
2021-04-02 17:09:01,544 ERROR: Exception on /buscar [POST] [in c:\users\erezzonico\proyectos\python\borisappfront\env\lib\site-packages\flask\app.py:1892]
Traceback (most recent call last):
  File "c:\users\erezzonico\proyectos\python\borisappfront\env\lib\site-packages\sqlalchemy\engine\base.py", line 1277, in _execute_context
    cursor, statement, parameters, context
  File "c:\users\erezzonico\proyectos\python\borisappfront\env\lib\site-packages\sqlalchemy\engine\default.py", line 593, in do_execute
    cursor.execute(statement, parameters)
sqlite3.IntegrityError: UNIQUE constraint failed: customer.id

The above exception was the direct cause of the following exception:

Traceback (most recent call last):
  File "c:\users\erezzonico\proyectos\python\borisappfront\env\lib\site-packages\flask\app.py", line 2447, in wsgi_app
    response = self.full_dispatch_request()
  File "c:\users\erezzonico\proyectos\python\borisappfront\env\lib\site-packages\flask\app.py", line 1952, in full_dispatch_request
    rv = self.handle_user_exception(e)
  File "c:\users\erezzonico\proyectos\python\borisappfront\env\lib\site-packages\flask\app.py", line 1821, in handle_user_exception
    reraise(exc_type, exc_value, tb)
  File "c:\users\erezzonico\proyectos\python\borisappfront\env\lib\site-packages\flask\_compat.py", line 39, in reraise
    raise value
  File "c:\users\erezzonico\proyectos\python\borisappfront\env\lib\site-packages\flask\app.py", line 1950, in full_dispatch_request
    rv = self.dispatch_request()
  File "c:\users\erezzonico\proyectos\python\borisappfront\env\lib\site-packages\flask\app.py", line 1936, in dispatch_request
    return self.view_functions[rule.endpoint](**req.view_args)
  File "C:\Users\erezzonico\Proyectos\Python\BorisAppFront\app\main\routes.py", line 67, in buscar
    cargar_pedido(unaEmpresa, pedido)
  File "C:\Users\erezzonico\Proyectos\Python\BorisAppFront\app\main\interface.py", line 424, in cargar_pedido
    db.session.commit()
  File "c:\users\erezzonico\proyectos\python\borisappfront\env\lib\site-packages\sqlalchemy\orm\scoping.py", line 163, in do
    return getattr(self.registry(), name)(*args, **kwargs)
  File "c:\users\erezzonico\proyectos\python\borisappfront\env\lib\site-packages\sqlalchemy\orm\session.py", line 1042, in commit
    self.transaction.commit()
  File "c:\users\erezzonico\proyectos\python\borisappfront\env\lib\site-packages\sqlalchemy\orm\session.py", line 504, in commit
    self._prepare_impl()
  File "c:\users\erezzonico\proyectos\python\borisappfront\env\lib\site-packages\sqlalchemy\orm\session.py", line 483, in _prepare_impl
    self.session.flush()
  File "c:\users\erezzonico\proyectos\python\borisappfront\env\lib\site-packages\sqlalchemy\orm\session.py", line 2536, in flush
    self._flush(objects)
  File "c:\users\erezzonico\proyectos\python\borisappfront\env\lib\site-packages\sqlalchemy\orm\session.py", line 2678, in _flush
    transaction.rollback(_capture_exception=True)
  File "c:\users\erezzonico\proyectos\python\borisappfront\env\lib\site-packages\sqlalchemy\util\langhelpers.py", line 70, in __exit__
    with_traceback=exc_tb,
  File "c:\users\erezzonico\proyectos\python\borisappfront\env\lib\site-packages\sqlalchemy\util\compat.py", line 182, in raise_
    raise exception
  File "c:\users\erezzonico\proyectos\python\borisappfront\env\lib\site-packages\sqlalchemy\orm\session.py", line 2638, in _flush
    flush_context.execute()
  File "c:\users\erezzonico\proyectos\python\borisappfront\env\lib\site-packages\sqlalchemy\orm\unitofwork.py", line 422, in execute
    rec.execute(self)
  File "c:\users\erezzonico\proyectos\python\borisappfront\env\lib\site-packages\sqlalchemy\orm\unitofwork.py", line 589, in execute
    uow,
  File "c:\users\erezzonico\proyectos\python\borisappfront\env\lib\site-packages\sqlalchemy\orm\persistence.py", line 245, in save_obj
    insert,
  File "c:\users\erezzonico\proyectos\python\borisappfront\env\lib\site-packages\sqlalchemy\orm\persistence.py", line 1083, in _emit_insert_statements
    c = cached_connections[connection].execute(statement, multiparams)
  File "c:\users\erezzonico\proyectos\python\borisappfront\env\lib\site-packages\sqlalchemy\engine\base.py", line 1011, in execute
    return meth(self, multiparams, params)
  File "c:\users\erezzonico\proyectos\python\borisappfront\env\lib\site-packages\sqlalchemy\sql\elements.py", line 298, in _execute_on_connection
    return connection._execute_clauseelement(self, multiparams, params)
  File "c:\users\erezzonico\proyectos\python\borisappfront\env\lib\site-packages\sqlalchemy\engine\base.py", line 1130, in _execute_clauseelement
    distilled_params,
  File "c:\users\erezzonico\proyectos\python\borisappfront\env\lib\site-packages\sqlalchemy\engine\base.py", line 1317, in _execute_context
    e, statement, parameters, cursor, context
  File "c:\users\erezzonico\proyectos\python\borisappfront\env\lib\site-packages\sqlalchemy\engine\base.py", line 1511, in _handle_dbapi_exception
    sqlalchemy_exception, with_traceback=exc_info[2], from_=e
  File "c:\users\erezzonico\proyectos\python\borisappfront\env\lib\site-packages\sqlalchemy\util\compat.py", line 182, in raise_
    raise exception
  File "c:\users\erezzonico\proyectos\python\borisappfront\env\lib\site-packages\sqlalchemy\engine\base.py", line 1277, in _execute_context
    cursor, statement, parameters, context
  File "c:\users\erezzonico\proyectos\python\borisappfront\env\lib\site-packages\sqlalchemy\engine\default.py", line 593, in do_execute
    cursor.execute(statement, parameters)
sqlalchemy.exc.IntegrityError: (sqlite3.IntegrityError) UNIQUE constraint failed: customer.id
[SQL: INSERT INTO customer (id, company_id, name, identification, email, phone, address, number, floor, zipcode, locality, city, province, country) VALUES (?, ?, ?, ?, ?, ?, ?, ?, ?, ?, ?, ?, ?, ?)]
[parameters: (58843800, 6, 'Esteban Rezzonico', '31544762', 'erezzonico@viu.com.ar', '', 'Cuba', '1965', '', '1428', '', 'Capital Federal', 'Capital Federal', 'AR')]
(Background on this error at: http://sqlalche.me/e/13/gkpj)
